[D 200204 22:06:09 Passport:10] debug msg
[I 200204 22:06:09 Passport:11] info msg
[W 200204 22:06:09 Passport:12] warning msg
[E 200204 22:06:09 Passport:13] error msg
[I 200204 22:06:09 web:2162] 304 GET / (127.0.0.1) 3.74ms
[D 200204 22:07:40 Passport:10] debug msg
[I 200204 22:07:40 Passport:11] info msg
[W 200204 22:07:40 Passport:12] warning msg
[E 200204 22:07:40 Passport:13] error msg
[I 200204 22:07:40 web:2162] 304 GET / (127.0.0.1) 2.63ms
[D 200205 21:05:22 Passport:10] debug msg
[I 200205 21:05:22 Passport:11] info msg
[W 200205 21:05:22 Passport:12] warning msg
[E 200205 21:05:22 Passport:13] error msg
[I 200205 21:05:22 web:2162] 304 GET / (127.0.0.1) 49.82ms
[W 200205 21:05:22 web:2162] 404 GET /favicon.ico (127.0.0.1) 14.19ms
[W 200205 21:06:26 web:2162] 404 GET /api?codeid=123&pcodeid= (127.0.0.1) 1.22ms
[E 200205 21:07:40 web:1670] Uncaught exception GET /api/imagecode?codeid=123&pcodeid= (127.0.0.1)
    HTTPServerRequest(protocol='http', host='127.0.0.1:8000', method='GET', uri='/api/imagecode?codeid=123&pcodeid=', version='HTTP/1.1', remote_ip='127.0.0.1')
    Traceback (most recent call last):
      File "/home/python/.virtualenvs/tornado/local/lib/python2.7/site-packages/tornado/web.py", line 1590, in _execute
        result = method(*self.path_args, **self.path_kwargs)
      File "/home/python/Desktop/Tornado_Project/handlers/VerifyCode.py", line 22, in get
        name, text, image = captcha.generate_captcha
    AttributeError: 'module' object has no attribute 'generate_captcha'
[E 200205 21:07:40 web:2162] 500 GET /api/imagecode?codeid=123&pcodeid= (127.0.0.1) 2.00ms
[I 200205 21:09:13 autoreload:199] /home/python/Desktop/Tornado_Project/handlers/VerifyCode.py modified; restarting server
[E 200205 21:09:26 web:1670] Uncaught exception GET /api/imagecode?codeid=123&pcodeid= (127.0.0.1)
    HTTPServerRequest(protocol='http', host='127.0.0.1:8000', method='GET', uri='/api/imagecode?codeid=123&pcodeid=', version='HTTP/1.1', remote_ip='127.0.0.1')
    Traceback (most recent call last):
      File "/home/python/.virtualenvs/tornado/local/lib/python2.7/site-packages/tornado/web.py", line 1590, in _execute
        result = method(*self.path_args, **self.path_kwargs)
      File "/home/python/Desktop/Tornado_Project/handlers/VerifyCode.py", line 22, in get
        name, text, image = captcha.generate_captcha()
    AttributeError: 'module' object has no attribute 'generate_captcha'
[E 200205 21:09:26 web:2162] 500 GET /api/imagecode?codeid=123&pcodeid= (127.0.0.1) 5.02ms
[I 200205 21:09:54 autoreload:199] server.py modified; restarting server
[I 200205 21:10:51 autoreload:199] /home/python/Desktop/Tornado_Project/handlers/VerifyCode.py modified; restarting server
[I 200205 21:10:55 autoreload:199] server.py modified; restarting server
[E 200205 21:11:15 web:1670] Uncaught exception GET /api/imagecode?codeid=123&pcodeid= (127.0.0.1)
    HTTPServerRequest(protocol='http', host='127.0.0.1:8000', method='GET', uri='/api/imagecode?codeid=123&pcodeid=', version='HTTP/1.1', remote_ip='127.0.0.1')
    Traceback (most recent call last):
      File "/home/python/.virtualenvs/tornado/local/lib/python2.7/site-packages/tornado/web.py", line 1590, in _execute
        result = method(*self.path_args, **self.path_kwargs)
      File "/home/python/Desktop/Tornado_Project/handlers/VerifyCode.py", line 22, in get
        name, text, image = captcha.generate_captcha()
    AttributeError: 'module' object has no attribute 'generate_captcha'
[E 200205 21:11:15 web:2162] 500 GET /api/imagecode?codeid=123&pcodeid= (127.0.0.1) 4.96ms
[I 200205 21:19:57 autoreload:199] /home/python/Desktop/Tornado_Project/handlers/VerifyCode.py modified; restarting server
[D 200205 21:20:07 Passport:10] debug msg
[I 200205 21:20:07 Passport:11] info msg
[W 200205 21:20:07 Passport:12] warning msg
[E 200205 21:20:07 Passport:13] error msg
[I 200205 21:20:07 web:2162] 200 GET / (127.0.0.1) 4.64ms
[D 200205 21:20:09 Passport:10] debug msg
[I 200205 21:20:09 Passport:11] info msg
[W 200205 21:20:09 Passport:12] warning msg
[E 200205 21:20:09 Passport:13] error msg
[I 200205 21:20:09 web:2162] 304 GET / (127.0.0.1) 2.33ms
[E 200205 21:20:19 web:1670] Uncaught exception GET /api/imagecode?codeid=123&pcodeid= (127.0.0.1)
    HTTPServerRequest(protocol='http', host='127.0.0.1:8000', method='GET', uri='/api/imagecode?codeid=123&pcodeid=', version='HTTP/1.1', remote_ip='127.0.0.1')
    Traceback (most recent call last):
      File "/home/python/.virtualenvs/tornado/local/lib/python2.7/site-packages/tornado/web.py", line 1590, in _execute
        result = method(*self.path_args, **self.path_kwargs)
      File "/home/python/Desktop/Tornado_Project/handlers/VerifyCode.py", line 22, in get
        name, text, image = captcha.captcha.generate_captcha()
      File "/home/python/Desktop/Tornado_Project/utils/captcha/captcha.py", line 219, in generate_captcha
        return self.captcha("")
      File "/home/python/Desktop/Tornado_Project/utils/captcha/captcha.py", line 205, in captcha
        image = self.text(image, self.fonts, drawings=['warp', 'rotate', 'offset'])
      File "/home/python/Desktop/Tornado_Project/utils/captcha/captcha.py", line 128, in text
        for size in font_sizes or (65, 70, 75)])
      File "/home/python/.virtualenvs/tornado/local/lib/python2.7/site-packages/PIL/ImageFont.py", line 640, in truetype
        return freetype(font)
      File "/home/python/.virtualenvs/tornado/local/lib/python2.7/site-packages/PIL/ImageFont.py", line 637, in freetype
        return FreeTypeFont(font, size, index, encoding, layout_engine)
      File "/home/python/.virtualenvs/tornado/local/lib/python2.7/site-packages/PIL/ImageFont.py", line 186, in __init__
        font, size, index, encoding, layout_engine=layout_engine
    IOError: cannot open resource
[E 200205 21:20:19 web:2162] 500 GET /api/imagecode?codeid=123&pcodeid= (127.0.0.1) 107.28ms
[E 200205 21:24:56 VerifyCode:26] 'Application' object has no attribute 'redis'
[I 200205 21:24:56 web:2162] 200 GET /api/imagecode?codeid=123&pcodeid= (127.0.0.1) 137.69ms
[I 200205 21:28:08 autoreload:199] /home/python/Desktop/Tornado_Project/handlers/BaseHandler.py modified; restarting server
[E 200205 21:32:04 VerifyCode:26] 'Application' object has no attribute 'redis'
[I 200205 21:32:04 web:2162] 200 GET /api/imagecode?codeid=123&pcodeid= (127.0.0.1) 61.76ms
[I 200205 21:39:54 autoreload:199] /home/python/Desktop/Tornado_Project/handlers/VerifyCode.py modified; restarting server
[I 200205 21:40:24 autoreload:199] /home/python/Desktop/Tornado_Project/handlers/VerifyCode.py modified; restarting server
[E 200205 21:40:57 VerifyCode:26] 'Application' object has no attribute 'redis'
[I 200205 21:40:57 web:2162] 200 GET /api/imagecode?codeid=123&pcodeid= (127.0.0.1) 56.58ms
[E 200205 21:41:01 VerifyCode:26] 'Application' object has no attribute 'redis'
[I 200205 21:41:01 web:2162] 200 GET /api/imagecode?codeid=123&pcodeid= (127.0.0.1) 25.21ms
[E 200205 21:47:40 VerifyCode:26] 'ImageCodeHandler' object has no attribute 'Application'
[I 200205 21:47:40 web:2162] 200 GET /api/imagecode?codeid=123&pcodeid= (127.0.0.1) 56.06ms
[I 200205 21:55:44 autoreload:199] /home/python/Desktop/Tornado_Project/handlers/BaseHandler.py modified; restarting server
[E 200205 21:57:40 VerifyCode:26] 'Application' object has no attribute 'redis'
[I 200205 21:57:40 web:2162] 200 GET /api/imagecode?codeid=123&pcodeid= (127.0.0.1) 57.17ms
[D 200205 22:25:37 Passport:10] debug msg
[I 200205 22:25:37 Passport:11] info msg
[W 200205 22:25:37 Passport:12] warning msg
[E 200205 22:25:37 Passport:13] error msg
[I 200205 22:25:37 web:2162] 304 GET / (127.0.0.1) 4.72ms
[W 200205 22:25:37 web:2162] 404 GET /favicon.ico (127.0.0.1) 10.29ms
[E 200205 22:25:43 VerifyCode:26] 'ImageCodeHandler' object has no attribute 're'
[I 200205 22:25:43 web:2162] 200 GET /api/imagecode?codeid=123&pcodeid= (127.0.0.1) 104.03ms
[I 200205 22:26:49 autoreload:199] /home/python/Desktop/Tornado_Project/handlers/BaseHandler.py modified; restarting server
[I 200205 22:26:55 autoreload:199] server.py modified; restarting server
[I 200205 22:27:05 autoreload:199] /home/python/Desktop/Tornado_Project/handlers/VerifyCode.py modified; restarting server
[I 200205 22:27:13 autoreload:199] /home/python/Desktop/Tornado_Project/handlers/VerifyCode.py modified; restarting server
[I 200205 22:27:22 autoreload:199] /home/python/Desktop/Tornado_Project/handlers/VerifyCode.py modified; restarting server
[E 200205 22:27:37 VerifyCode:26] 'Application' object has no attribute 'redis'
[I 200205 22:27:37 web:2162] 200 GET /api/imagecode?codeid=123&pcodeid= (127.0.0.1) 61.23ms
[I 200205 22:29:21 autoreload:199] /home/python/Desktop/Tornado_Project/handlers/VerifyCode.py modified; restarting server
[I 200205 22:32:47 autoreload:199] /home/python/Desktop/Tornado_Project/handlers/BaseHandler.py modified; restarting server
[I 200206 20:42:39 web:2162] 304 GET / (127.0.0.1) 0.65ms
[W 200206 20:42:39 web:2162] 404 GET /favicon.ico (127.0.0.1) 5.64ms
[E 200206 20:42:42 VerifyCode:26] 'Application' object has no attribute 'redis'
[I 200206 20:42:42 web:2162] 200 GET /api/imagecode?codeid=123&pcodeid= (127.0.0.1) 42.65ms
[I 200206 20:44:28 autoreload:199] /home/python/Desktop/Tornado_Project/handlers/VerifyCode.py modified; restarting server
[E 200206 20:44:44 web:1670] Uncaught exception GET /api/imagecode?codeid=123&pcodeid= (127.0.0.1)
    HTTPServerRequest(protocol='http', host='127.0.0.1:8000', method='GET', uri='/api/imagecode?codeid=123&pcodeid=', version='HTTP/1.1', remote_ip='127.0.0.1')
    Traceback (most recent call last):
      File "/home/python/.virtualenvs/tornado/local/lib/python2.7/site-packages/tornado/web.py", line 1590, in _execute
        result = method(*self.path_args, **self.path_kwargs)
      File "/home/python/Desktop/Tornado_Project/handlers/VerifyCode.py", line 24, in get
        self.redis.setex("image_code_%s" % code_id, constants.IMAGE_CODE_EXPIRES_SECONDS, text)
      File "/home/python/Desktop/Tornado_Project/handlers/BaseHandler.py", line 15, in redis
        return self.application.redis
    AttributeError: 'Application' object has no attribute 'redis'
[E 200206 20:44:44 web:2162] 500 GET /api/imagecode?codeid=123&pcodeid= (127.0.0.1) 21.68ms
[I 200206 20:54:24 autoreload:199] server.py modified; restarting server
[E 200206 21:38:41 torndb:103] Cannot connect to MySQL on 127.0.0.1
    Traceback (most recent call last):
      File "/home/python/.virtualenvs/tornado/local/lib/python2.7/site-packages/torndb.py", line 100, in __init__
        self.reconnect()
      File "/home/python/.virtualenvs/tornado/local/lib/python2.7/site-packages/torndb.py", line 117, in reconnect
        self._db = MySQLdb.connect(**self._db_args)
      File "/home/python/.virtualenvs/tornado/local/lib/python2.7/site-packages/MySQLdb/__init__.py", line 81, in Connect
        return Connection(*args, **kwargs)
      File "/home/python/.virtualenvs/tornado/local/lib/python2.7/site-packages/MySQLdb/connections.py", line 193, in __init__
        super(Connection, self).__init__(*args, **kwargs2)
    OperationalError: (1049, "Unknown database 'ihome'")
[I 200206 21:38:46 web:2162] 200 GET /api/imagecode?codeid=123&pcodeid= (127.0.0.1) 91.35ms
[I 200206 21:40:51 autoreload:199] /home/python/Desktop/Tornado_Project/handlers/VerifyCode.py modified; restarting server
[E 200206 21:40:52 torndb:103] Cannot connect to MySQL on 127.0.0.1
    Traceback (most recent call last):
      File "/home/python/.virtualenvs/tornado/local/lib/python2.7/site-packages/torndb.py", line 100, in __init__
        self.reconnect()
      File "/home/python/.virtualenvs/tornado/local/lib/python2.7/site-packages/torndb.py", line 117, in reconnect
        self._db = MySQLdb.connect(**self._db_args)
      File "/home/python/.virtualenvs/tornado/local/lib/python2.7/site-packages/MySQLdb/__init__.py", line 81, in Connect
        return Connection(*args, **kwargs)
      File "/home/python/.virtualenvs/tornado/local/lib/python2.7/site-packages/MySQLdb/connections.py", line 193, in __init__
        super(Connection, self).__init__(*args, **kwargs2)
    OperationalError: (1049, "Unknown database 'ihome'")
[I 200206 21:42:26 web:2162] 200 GET /api/imagecode?codeid=123&pcodeid= (127.0.0.1) 58.15ms
[I 200206 21:42:42 web:2162] 200 GET /api/imagecode?codeid=123&pcodeid= (127.0.0.1) 24.68ms
[I 200206 21:43:30 web:2162] 200 GET /api/imagecode?codeid=12&pcodeid=123 (127.0.0.1) 31.24ms
[I 200206 22:12:28 autoreload:199] /home/python/Desktop/Tornado_Project/handlers/VerifyCode.py modified; restarting server
[E 200206 22:12:28 torndb:103] Cannot connect to MySQL on 127.0.0.1
    Traceback (most recent call last):
      File "/home/python/.virtualenvs/tornado/local/lib/python2.7/site-packages/torndb.py", line 100, in __init__
        self.reconnect()
      File "/home/python/.virtualenvs/tornado/local/lib/python2.7/site-packages/torndb.py", line 117, in reconnect
        self._db = MySQLdb.connect(**self._db_args)
      File "/home/python/.virtualenvs/tornado/local/lib/python2.7/site-packages/MySQLdb/__init__.py", line 81, in Connect
        return Connection(*args, **kwargs)
      File "/home/python/.virtualenvs/tornado/local/lib/python2.7/site-packages/MySQLdb/connections.py", line 193, in __init__
        super(Connection, self).__init__(*args, **kwargs2)
    OperationalError: (1049, "Unknown database 'ihome'")
[I 200206 22:20:06 autoreload:199] /home/python/Desktop/Tornado_Project/constants.py modified; restarting server
[E 200206 22:20:07 torndb:103] Cannot connect to MySQL on 127.0.0.1
    Traceback (most recent call last):
      File "/home/python/.virtualenvs/tornado/local/lib/python2.7/site-packages/torndb.py", line 100, in __init__
        self.reconnect()
      File "/home/python/.virtualenvs/tornado/local/lib/python2.7/site-packages/torndb.py", line 117, in reconnect
        self._db = MySQLdb.connect(**self._db_args)
      File "/home/python/.virtualenvs/tornado/local/lib/python2.7/site-packages/MySQLdb/__init__.py", line 81, in Connect
        return Connection(*args, **kwargs)
      File "/home/python/.virtualenvs/tornado/local/lib/python2.7/site-packages/MySQLdb/connections.py", line 193, in __init__
        super(Connection, self).__init__(*args, **kwargs2)
    OperationalError: (1049, "Unknown database 'ihome'")
[I 200206 22:31:30 autoreload:199] /home/python/Desktop/Tornado_Project/handlers/VerifyCode.py modified; restarting server
[I 200206 23:19:00 autoreload:199] /home/python/Desktop/Tornado_Project/config.py modified; restarting server
[I 200206 23:19:13 web:2162] 200 GET /api/imagecode?codeid=12&pcodeid=123 (127.0.0.1) 165.61ms
[E 200206 23:20:22 web:1670] Uncaught exception POST /api/smscode (127.0.0.1)
    HTTPServerRequest(protocol='http', host='127.0.0.1:8000', method='POST', uri='/api/smscode', version='HTTP/1.1', remote_ip='127.0.0.1')
    Traceback (most recent call last):
      File "/home/python/.virtualenvs/tornado/local/lib/python2.7/site-packages/tornado/web.py", line 1590, in _execute
        result = method(*self.path_args, **self.path_kwargs)
      File "/home/python/Desktop/Tornado_Project/handlers/VerifyCode.py", line 39, in post
        mobile = self.json_args.get("mobile")
    AttributeError: 'NoneType' object has no attribute 'get'
[E 200206 23:20:22 web:2162] 500 POST /api/smscode (127.0.0.1) 14.99ms
[I 200206 23:24:41 web:2162] 200 GET /api/imagecode?codeid=12&pcodeid=123 (127.0.0.1) 30.53ms
[I 200206 23:25:10 web:2162] 200 POST /api/smscode (127.0.0.1) 55.22ms
[I 200206 23:27:10 web:2162] 200 GET /api/imagecode?codeid=12&pcodeid=123 (127.0.0.1) 24.44ms
[I 200206 23:27:36 web:2162] 200 POST /api/smscode (127.0.0.1) 1.56ms
[I 200206 23:30:20 web:2162] 200 POST /api/smscode (127.0.0.1) 1.08ms
[I 200206 23:31:21 web:2162] 200 GET /api/imagecode?codeid=123&pcodeid=12 (127.0.0.1) 24.86ms
[E 200206 23:31:57 VerifyCode:69] '_CCP' object has no attribute 'sendTemplateSMS'
[I 200206 23:31:57 web:2162] 200 POST /api/smscode (127.0.0.1) 49.51ms
[I 200206 23:34:12 autoreload:199] /home/python/Desktop/Tornado_Project/libs/yuntongxun/CCP.py modified; restarting server
[I 200206 23:34:17 autoreload:199] /home/python/Desktop/Tornado_Project/handlers/VerifyCode.py modified; restarting server
[I 200206 23:34:35 web:2162] 200 GET /api/imagecode?codeid=123&pcodeid=12 (127.0.0.1) 111.53ms
[E 200206 23:34:52 VerifyCode:71] '_CCP' object has no attribute 'sendTemplateSMS'
[I 200206 23:34:52 web:2162] 200 POST /api/smscode (127.0.0.1) 3.43ms
[I 200206 23:37:53 autoreload:199] /home/python/Desktop/Tornado_Project/libs/yuntongxun/CCP.py modified; restarting server
[I 200206 23:40:37 web:2162] 200 GET /api/imagecode?codeid=123&pcodeid=12 (127.0.0.1) 54.08ms
[E 200206 23:40:51 VerifyCode:71] '_CCP' object has no attribute 'sendTemplateSMS'
[I 200206 23:40:51 web:2162] 200 POST /api/smscode (127.0.0.1) 50.23ms
[I 200206 23:43:17 autoreload:199] /home/python/Desktop/Tornado_Project/libs/yuntongxun/CCP.py modified; restarting server
[I 200206 23:58:10 web:2162] 200 GET /api/imagecode?codeid=123&pcodeid=12 (127.0.0.1) 59.58ms
[I 200206 23:58:50 web:2162] 200 POST /api/smscode (127.0.0.1) 330.06ms
[I 200207 00:00:57 web:2162] 200 GET /api/imagecode?codeid=123&pcodeid=12 (127.0.0.1) 25.71ms
[I 200207 00:01:23 web:2162] 200 POST /api/smscode (127.0.0.1) 209.76ms
[I 200207 00:38:00 autoreload:199] /home/python/Desktop/Tornado_Project/handlers/VerifyCode.py modified; restarting server
